20 Dec 2017 07:08:47 : darth, general, darth kota#9446, i already did
20 Dec 2017 07:08:57 : darth, general, darth kota#9446, ;join
20 Dec 2017 07:08:58 : darth, general, darthbot98#5182, You are not connected to a voice channel!
20 Dec 2017 07:09:20 : darth, general, Wertfuzzy77#0274, ;join
20 Dec 2017 07:09:22 : darth, general, darthbot98#5182, Reconnected channel!
20 Dec 2017 07:09:32 : darth, general, Wertfuzzy77#0274, ;forceplay https://www.youtube.com/watch?v=e7aGAIWe3uE
20 Dec 2017 07:09:46 : darth, general, darth kota#9446, Traceback (most recent call last):
  File "C:\Users\Dakota\AppData\Local\Programs\Python\Python36\lib\site-packages\discord\ext\commands\core.py", line 50, in wrapped
    ret = yield from coro(*args, **kwargs)
  File "C:\Users\Dakota\Downloads\Botfuzzy77-master\Botfuzzy77-master\Modules\Music.py", line 259, in forceplay
    current = await SP.voice.create_ytdl_player(link, ytdl_options=OPTS)
AttributeError: 'NoneType' object has no attribute 'create_ytdl_player'

The above exception was the direct cause of the following exception:

Traceback (most recent call last):
  File "C:\Users\Dakota\AppData\Local\Programs\Python\Python36\lib\site-packages\discord\ext\commands\bot.py", line 846, in process_commands
    yield from command.invoke(ctx)
  File "C:\Users\Dakota\AppData\Local\Programs\Python\Python36\lib\site-packages\discord\ext\commands\core.py", line 374, in invoke
    yield from injected(*ctx.args, **ctx.kwargs)
  File "C:\Users\Dakota\AppData\Local\Programs\Python\Python36\lib\site-packages\discord\ext\commands\core.py", line 54, in wrapped
    raise CommandInvokeError(e) from e
discord.ext.commands.errors.CommandInvokeError: Command raised an exception: AttributeError: 'NoneType' object has no attribute 'create_ytdl_player'
20 Dec 2017 07:09:51 : darth, general, Wertfuzzy77#0274, ;debug 1
20 Dec 2017 07:09:59 : darth, general, Wertfuzzy77#0274, hmmmmm
20 Dec 2017 07:10:01 : darth, general, darth kota#9446, ;debug 1
20 Dec 2017 07:10:02 : darth, general, darthbot98#5182, ```py
1
```
20 Dec 2017 07:10:03 : darth, general, Wertfuzzy77#0274, rip my prems
20 Dec 2017 07:10:10 : darth, general, Wertfuzzy77#0274, perms*
20 Dec 2017 07:10:28 : darth, general, Wertfuzzy77#0274, `;gamesdebug self.serverPlayers[ctx.message.server.id]`
20 Dec 2017 07:10:31 : darth, general, darth kota#9446, well it was easier to bulk replace your id with mine\
20 Dec 2017 07:10:44 : darth, general, Wertfuzzy77#0274, do that
20 Dec 2017 07:10:46 : darth, general, darth kota#9446, ;gamesdebug self.serverPlayers[ctx.message.server.id]
20 Dec 2017 07:10:54 : darth, general, Wertfuzzy77#0274, error?
20 Dec 2017 07:11:03 : darth, general, Wertfuzzy77#0274, o wait
20 Dec 2017 07:11:04 : darth, general, Wertfuzzy77#0274, i dumb
20 Dec 2017 07:11:29 : darth, general, Wertfuzzy77#0274, `;musicdebug self.serverPlayers[ctx.message.server.id]`
20 Dec 2017 07:11:40 : darth, general, darth kota#9446, ;musicdebug self.serverPlayers[ctx.message.server.id]
20 Dec 2017 07:11:52 : darth, general, darth kota#9446, nothing
20 Dec 2017 07:12:03 : darth, general, Wertfuzzy77#0274, `;musicdebug 1`
20 Dec 2017 07:12:32 : darth, general, Wertfuzzy77#0274, ayy wait
20 Dec 2017 07:12:35 : darth, general, Wertfuzzy77#0274, ;musicdebug 1
20 Dec 2017 07:12:35 : darth, general, darthbot98#5182, ```py
1
```
20 Dec 2017 07:12:37 : darth, general, Wertfuzzy77#0274, we did it
20 Dec 2017 07:12:41 : darth, general, darth kota#9446, lol
20 Dec 2017 07:12:44 : darth, general, Wertfuzzy77#0274, ;musicdebug self.serverPlayers[ctx.message.server.id]
20 Dec 2017 07:13:13 : darth, general, darth kota#9446, Ignoring exception in command musicdebug
Traceback (most recent call last):
  File "C:\Users\Dakota\AppData\Local\Programs\Python\Python36\lib\site-packages\discord\ext\commands\core.py", line 50, in wrapped
    ret = yield from coro(*args, **kwargs)
  File "C:\Users\Dakota\Downloads\Botfuzzy77-master\Botfuzzy77-master\Modules\Music.py", line 643, in musicdebug
    await self.bot.say(python.format(result))
  File "C:\Users\Dakota\Downloads\Botfuzzy77-master\Botfuzzy77-master\Modules\Music.py", line 138, in __str__
    ret += "Connected Channel: {}\n".format(self.voice.channel)
AttributeError: 'NoneType' object has no attribute 'channel'

The above exception was the direct cause of the following exception:

Traceback (most recent call last):
  File "C:\Users\Dakota\AppData\Local\Programs\Python\Python36\lib\site-packages\discord\ext\commands\bot.py", line 846, in process_commands
    yield from command.invoke(ctx)
  File "C:\Users\Dakota\AppData\Local\Programs\Python\Python36\lib\site-packages\discord\ext\commands\core.py", line 374, in invoke
    yield from injected(*ctx.args, **ctx.kwargs)
  File "C:\Users\Dakota\AppData\Local\Programs\Python\Python36\lib\site-packages\discord\ext\commands\core.py", line 54, in wrapped
    raise CommandInvokeError(e) from e
discord.ext.commands.errors.CommandInvokeError: Command raised an exception: AttributeError: 'NoneType' object has no attribute 'channel'
20 Dec 2017 07:13:21 : darth, general, darth kota#9446, reeeeeeeee
20 Dec 2017 07:13:23 : darth, general, Wertfuzzy77#0274, wat
20 Dec 2017 07:13:34 : darth, general, Wertfuzzy77#0274, ;musicdebug self.serverPlayers
20 Dec 2017 07:13:36 : darth, general, darthbot98#5182, ```py
{'310998763349213196': <Modules.Music.ServerPlayer object at 0x000002658793D668>}
```
20 Dec 2017 07:13:55 : darth, general, Wertfuzzy77#0274, ;musicdebug self.serverPlayers[ctx.message.server.id].player
20 Dec 2017 07:13:55 : darth, general, darthbot98#5182, ```py
None
```
20 Dec 2017 07:14:00 : darth, general, Wertfuzzy77#0274, ;musicdebug self.serverPlayers[ctx.message.server.id].voice
20 Dec 2017 07:14:00 : darth, general, darthbot98#5182, ```py
None
```
20 Dec 2017 07:14:05 : darth, general, Wertfuzzy77#0274, why are you none???
20 Dec 2017 07:14:09 : darth, general, darth kota#9446, has died to death
20 Dec 2017 07:14:36 : darth, general, Wertfuzzy77#0274, ;musicdebug self.bot.join_voice_channel(ctx.message.author.voice_channel)
20 Dec 2017 07:14:43 : darth, general, Wertfuzzy77#0274, ;musicdebug self.serverPlayers[ctx.message.server.id].voice
20 Dec 2017 07:14:43 : darth, general, darthbot98#5182, ```py
None
```
20 Dec 2017 07:14:45 : darth, general, Wertfuzzy77#0274, die
20 Dec 2017 07:14:51 : darth, general, Wertfuzzy77#0274, rip
20 Dec 2017 07:14:56 : darth, general, Wertfuzzy77#0274, what was the error?
20 Dec 2017 07:16:31 : darth, general, darth kota#9446, the fucking char cap
20 Dec 2017 07:16:46 : darth, general, darth kota#9446, Traceback (most recent call last):
  File "C:\Users\Dakota\AppData\Local\Programs\Python\Python36\lib\site-packages\discord\ext\commands\bot.py", line 846, in process_commands
    yield from command.invoke(ctx)
  File "C:\Users\Dakota\AppData\Local\Programs\Python\Python36\lib\site-packages\discord\ext\commands\core.py", line 374, in invoke
    yield from injected(*ctx.args, **ctx.kwargs)
  File "C:\Users\Dakota\AppData\Local\Programs\Python\Python36\lib\site-packages\discord\ext\commands\core.py", line 54, in wrapped
    raise CommandInvokeError(e) from e
discord.ext.commands.errors.CommandInvokeError: Command raised an exception: AttributeError: 'NoneType' object has no attribute 'channel'
Ignoring exception in command musicdebug
Traceback (most recent call last):
  File "C:\Users\Dakota\AppData\Local\Programs\Python\Python36\lib\site-packages\discord\ext\commands\core.py", line 50, in wrapped
    ret = yield from coro(*args, **kwargs)
  File "C:\Users\Dakota\Downloads\Botfuzzy77-master\Botfuzzy77-master\Modules\Music.py", line 641, in musicdebug
    result = await result
  File "C:\Users\Dakota\AppData\Local\Programs\Python\Python36\lib\site-packages\discord\client.py", line 3198, in join_voice_channel
    raise e
20 Dec 2017 07:16:49 : darth, general, darth kota#9446, File "C:\Users\Dakota\AppData\Local\Programs\Python\Python36\lib\site-packages\discord\client.py", line 3195, in join_voice_channel
    data = yield from asyncio.wait_for(voice_data_future, timeout=10.0, loop=self.loop)
  File "C:\Users\Dakota\AppData\Local\Programs\Python\Python36\lib\asyncio\tasks.py", line 362, in wait_for
    raise futures.TimeoutError()
concurrent.futures._base.TimeoutError

The above exception was the direct cause of the following exception:

Traceback (most recent call last):
  File "C:\Users\Dakota\AppData\Local\Programs\Python\Python36\lib\site-packages\discord\ext\commands\bot.py", line 846, in process_commands
    yield from command.invoke(ctx)
  File "C:\Users\Dakota\AppData\Local\Programs\Python\Python36\lib\site-packages\discord\ext\commands\core.py", line 374, in invoke
    yield from injected(*ctx.args, **ctx.kwargs)
  File "C:\Users\Dakota\AppData\Local\Programs\Python\Python36\lib\site-packages\discord\ext\commands\core.py", line 54, in wrapped
    raise CommandInvokeError(e) from e
discord.ext.commands.errors.CommandInvokeError: Command raised an exception: TimeoutError:
20 Dec 2017 07:17:49 : darth, general, Wertfuzzy77#0274, ;musicdebug self.bot.join_voice_channel(ctx.message.author.voice_channel)
20 Dec 2017 07:17:53 : darth, general, Wertfuzzy77#0274, ;musicdebug self.serverPlayers[ctx.message.server.id].voice
20 Dec 2017 07:17:55 : darth, general, darthbot98#5182, ```py
None
```
20 Dec 2017 07:17:57 : darth, general, Wertfuzzy77#0274, buh
20 Dec 2017 07:18:02 : darth, general, Wertfuzzy77#0274, o wait
20 Dec 2017 07:18:05 : darth, general, Wertfuzzy77#0274, ;leave
20 Dec 2017 07:18:08 : darth, general, Wertfuzzy77#0274, nu
20 Dec 2017 07:18:13 : darth, general, Wertfuzzy77#0274, feelsbad
20 Dec 2017 07:18:16 : darth, general, Wertfuzzy77#0274, ;join
20 Dec 2017 07:18:28 : darth, general, darthbot98#5182, Reconnected channel!
20 Dec 2017 07:18:30 : darth, general, Wertfuzzy77#0274, WAIT
20 Dec 2017 07:18:34 : darth, general, Wertfuzzy77#0274, I HAD THIS BEFORE
20 Dec 2017 07:18:36 : darth, general, Wertfuzzy77#0274, WHAT DID I DO
20 Dec 2017 07:18:40 : darth, general, Wertfuzzy77#0274, I REMEMBER
20 Dec 2017 07:19:07 : darth, general, Wertfuzzy77#0274, do `pip install --upgrade discord.py[voice]`
